<?xml version="1.0" ?>
<!-- =================================================================================== -->
<!-- |    This document was autogenerated by xacro from /smart_grasping_sandbox/src/smart_grasping_sandbox/fh_desc/robots/right_H1_ur5.urdf | -->
<!-- |    EDITING THIS FILE BY HAND IS NOT RECOMMENDED                                 | -->
<!-- =================================================================================== -->
<robot name="smart_grasping_sandbox" xmlns:xacro="http://ros.org/wiki/xacro">
  <!--
  Author: Kelsey Hawkins
  Contributers: Jimmy Da Silva, Ajit Krisshna N L, Muhammad Asif Rana
-->
  <!-- Inertia parameters -->
  <!-- This mass might be incorrect -->
  <!-- These parameters are borrowed from the urcontrol.conf file
       but are not verified for the correct permutation.
       The permutation was guessed by looking at the UR5 parameters.
       Serious use of these parameters needs further inspection. -->
  <!-- Kinematic model -->
  <!-- Properties from urcontrol.conf -->
  <!-- Arbitrary offsets for shoulder/elbow joints -->
  <!-- measured from model -->
  <!-- measured from model -->
  <!-- link lengths used in model -->
  <link name="world"/>
  
  <link name="table">
    <visual>
      <geometry>
        <box size="0.6 0.6 0.05"/>
      </geometry>
    </visual>
    <collision>
      <geometry>
        <box size="0.6 0.6 0.05"/>
      </geometry>
    </collision>
  </link>
  
  <joint name="world_to_table" type="fixed">
    <parent link="world"/>
    <child link="table"/>
    <origin xyz="0.0 0.0 0.5" rpy="0.0 0.0 0.0"/>
  </joint>
  
  <joint name="table_to_hand" type="fixed">
    <parent link="table"/>
    <child link="H1_base_attach"/>
    <origin xyz="0.0 0.0 0.05" rpy="0.0 0.0 0.0"/>
  </joint>
  
  
  
  <link name="H1_base_attach"/>
  <material name="Blue">
    <color rgba="0.0 0.0 0.8 1.0"/>
  </material>
  <material name="Green">
    <color rgba="0.0 0.8 0.0 1.0"/>
  </material>
  <material name="BiotacGreen">
    <color rgba="0.31 0.85 0.42 1.0"/>
  </material>
  <material name="Grey">
    <color rgba="0.2 0.2 0.2 1.0"/>
  </material>
  <material name="LightGrey">
    <color rgba="0.6 0.6 0.6 1.0"/>
  </material>
  <material name="Red">
    <color rgba="0.8 0.0 0.0 1.0"/>
  </material>
  <material name="White">
    <color rgba="1.0 1.0 1.0 1.0"/>
  </material>
  <gazebo>
    <plugin filename="libgazebo_ros_control.so" name="ros_control">
      <robotSimType>gazebo_ros_control/DefaultRobotHWSim</robotSimType>
    </plugin>
  </gazebo>
  <link name="H1_base_link">
    <inertial>
      <origin rpy="0 0 0" xyz="-8.6116E-06 -0.0058125 0.028294"/>
      <mass value="0.07527"/>
      <inertia ixx="0.00014442" ixy="1.2033E-08" ixz="-5.9646E-10" iyy="0.00014979" iyz="-1.0288E-05" izz="5.2943E-05"/>
    </inertial>
    <visual>
      <origin rpy="0 0 0" xyz="0 0 0"/>
      <geometry>
        <mesh filename="package://fh_desc/meshes/v2/palm_link_simple.dae"/>
      </geometry>
      <material name="light_grey">
        <color rgba="0.75 0.75 0.75 1.0"/>
      </material>
    </visual>
    <collision>
      <origin rpy="0 0 0" xyz="0 0 0"/>
      <geometry>
        <mesh filename="package://fh_desc/meshes/v2/palm_link_simple.dae"/>
      </geometry>
      <material name="light_grey">
        <color rgba="0.75 0.75 0.75 1.0"/>
      </material>
    </collision>
  </link>
  <joint name="H1Base" type="fixed">
    <origin rpy="0 0 0" xyz="0 0 0"/>
    <parent link="H1_base_attach"/>
    <child link="H1_wrist_attach"/>
  </joint>
  
  <gazebo>
    <plugin name="imu_controller" filename="libgazebo_ros_imu.so">
      <alwaysOn>true</alwaysOn>
      <updateRate>50</updateRate>
      <bodyName>H1_base_link</bodyName>
      <!--imu_link -->
      <topicName>imu/data</topicName>
      <serviceName>imu/is_calibrated</serviceName>
      <gaussianNoise>2.89e-08</gaussianNoise>
      <xyzOffsets>0 0 0</xyzOffsets>
      <rpyOffsets>0 0 0</rpyOffsets>
    </plugin>
  </gazebo>
  
  <link name="H1_insert_F1"/>
  <joint name="H1_dummy_joint_1" type="fixed">
    <origin rpy="0 0 2.3562" xyz="-0.045 -0.025981 0"/>
    <axis xyz="0 -1 0"/>
    <parent link="H1_base_link"/>
    <child link="H1_insert_F1"/>
  </joint>
  <link name="H1_insert_F2"/>
  <joint name="H1_dummy_joint_2" type="fixed">
    <origin rpy="0 0 0" xyz="0 0.029019 0"/>
    <axis xyz="0 -1 0"/>
    <parent link="H1_base_link"/>
    <child link="H1_insert_F2"/>
  </joint>
  <link name="H1_insert_F3"/>
  <joint name="H1_dummy_joint_3" type="fixed">
    <origin rpy="0 0 -2.3562" xyz="0.045 -0.025981 0"/>
    <axis xyz="0 -1 0"/>
    <parent link="H1_base_link"/>
    <child link="H1_insert_F3"/>
  </joint>
  <link name="H1_wrist_attach"/>
  <joint name="H1_base_link_wrist_attach" type="fixed">
    <origin rpy="0 0 0" xyz="0 0 -0.0005"/>
    <child link="H1_base_link"/>
    <parent link="H1_wrist_attach"/>
  </joint>
  <link name="H1_F1_palm_link">
    <inertial>
      <origin rpy="0 0 0" xyz="-0.00681802120880393 -0.00947020456878004 0.067587996682422"/>
      <mass value="0.0341482312344481"/>
      <inertia ixx="2.79747833772125E-05" ixy="-5.50900644725373E-08" ixz="-2.82072424927723E-07" iyy="2.67800858812928E-05" iyz="3.1953125069394E-06" izz="9.86122271726361E-06"/>
    </inertial>
    <visual>
      <origin rpy="0 0 0" xyz="0 0 0"/>
      <geometry>
        <mesh filename="package://fh_desc/meshes/v2/finger_palm_link.dae"/>
      </geometry>
      <material name="light_grey">
        <color rgba="0.75 0.75 0.75 1.0"/>
      </material>
    </visual>
    <!-- Collision mesh no needed as it is part of palm_link_simple.dae collision mesh -->
    <!--xacro:mesh_collision file_name="v2/finger_palm_link.dae">
        <origin xyz="0 0 0" rpy="0 0 0" />
        <xacro:light_grey/>
      </xacro:mesh_collision-->
  </link>
  <link name="H1_F1_base_link">
    <inertial>
      <origin rpy="0 0 0" xyz="-0.000142856770000038 0.0265691681336443 0.0538751581621436"/>
      <mass value="0.174652229503358"/>
      <inertia ixx="0.000298372741514267" ixy="-5.05751882577435E-07" ixz="1.94982779411417E-07" iyy="0.000299629589232877" iyz="2.79565205733806E-05" izz="0.000134889645145365"/>
    </inertial>
    <visual>
      <origin rpy="0 0 0" xyz="0 0 0"/>
      <geometry>
        <mesh filename="package://fh_desc/meshes/v2/finger_base_link_simple.dae"/>
      </geometry>
      <material name="light_grey">
        <color rgba="0.75 0.75 0.75 1.0"/>
      </material>
    </visual>
    <collision>
      <origin rpy="0 0 0" xyz="0 0 0"/>
      <geometry>
        <mesh filename="package://fh_desc/meshes/v2/finger_base_link_simple.dae"/>
      </geometry>
      <material name="light_grey">
        <color rgba="0.75 0.75 0.75 1.0"/>
      </material>
    </collision>
  </link>
  <link name="H1_F1_link_1">
    <inertial>
      <origin rpy="0 0 0" xyz="-0.000141876508729455 -0.00135409566494088 0.0277606215980989"/>
      <mass value="0.0827759744227546"/>
      <inertia ixx="4.61070151157777E-05" ixy="7.47741111557837E-08" ixz="-2.25165057702697E-07" iyy="5.27678327317508E-05" iyz="-3.64603343546298E-07" izz="2.89599551320955E-05"/>
    </inertial>
    <visual>
      <origin rpy="0 0 0" xyz="0 0 0"/>
      <geometry>
        <mesh filename="package://fh_desc/meshes/v2/finger_prox_link_simple.dae"/>
      </geometry>
      <material name="light_grey">
        <color rgba="0.75 0.75 0.75 1.0"/>
      </material>
    </visual>
    <collision>
      <origin rpy="0 0 0" xyz="0 0 0"/>
      <geometry>
        <mesh filename="package://fh_desc/meshes/v2/finger_prox_link_simple.dae"/>
      </geometry>
      <material name="light_grey">
        <color rgba="0.75 0.75 0.75 1.0"/>
      </material>
    </collision>
  </link>
  <link name="H1_F1_link_2">
    <inertial>
      <origin rpy="0 0 0" xyz="0.000506812071918918 -0.00091292934992606 0.0156620851768385"/>
      <mass value="0.0270049614151599"/>
      <inertia ixx="1.06942730265546E-05" ixy="-7.1810089794211E-09" ixz="-3.49957211410822E-07" iyy="1.05772889540593E-05" iyz="-8.38595987731518E-07" izz="3.27173446995846E-06"/>
    </inertial>
    <visual>
      <origin rpy="0 0 0" xyz="0 0 0"/>
      <geometry>
        <mesh filename="package://fh_desc/meshes/v2/finger_dist_link_simple.dae"/>
      </geometry>
      <material name="light_grey">
        <color rgba="0.75 0.75 0.75 1.0"/>
      </material>
    </visual>
    <collision>
      <origin rpy="0 0 0" xyz="0 0 0"/>
      <geometry>
        <mesh filename="package://fh_desc/meshes/v2/finger_dist_link_simple.dae"/>
      </geometry>
      <material name="light_grey">
        <color rgba="0.75 0.75 0.75 1.0"/>
      </material>
    </collision>
  </link>
  <joint name="H1_F1Palm" type="fixed">
    <origin rpy="0 0 0" xyz="0 0 0"/>
    <parent link="H1_insert_F1"/>
    <child link="H1_F1_palm_link"/>
  </joint>
  <joint name="H1_F1J1" type="revolute">
    <origin rpy="-8.8818E-16 -1.0061E-16 0.022402" xyz="0 0 0.00016528"/>
    <axis xyz="0 0 1"/>
    <parent link="H1_F1_palm_link"/>
    <child link="H1_F1_base_link"/>
    <limit effort="50" lower="-0.785398163397" upper="0.785398163397" velocity="1.0"/>
    <dynamics damping="0.0" friction="0.0"/>
  </joint>
  <joint name="H1_F1J2" type="revolute">
    <origin rpy="0.070695 6.9389E-16 2.0947E-16" xyz="0 0.035 0.11683"/>
    <axis xyz="1 0 0"/>
    <parent link="H1_F1_base_link"/>
    <child link="H1_F1_link_1"/>
    <limit effort="50" lower="-1.3962634016" upper="1.0471975512" velocity="1.0"/>
    <dynamics damping="0.0" friction="0.0"/>
  </joint>
  <joint name="H1_F1J3" type="revolute">
    <origin rpy="-0.0068649 1.7347E-18 1.6176E-16" xyz="0 0 0.06"/>
    <axis xyz="1 0 0"/>
    <parent link="H1_F1_link_1"/>
    <child link="H1_F1_link_2"/>
    <limit effort="50" lower="-1.0471975512" upper="1.57079632679" velocity="1.0"/>
    <dynamics damping="0.0" friction="0.0"/>
  </joint>
  <transmission name="H1_F1J1_transmission">
    <type>transmission_interface/SimpleTransmission</type>
    <actuator name="H1_F1J1">
      <mechanicalReduction>1</mechanicalReduction>
    </actuator>
    <joint name="H1_F1J1">
      <hardwareInterface>EffortJointInterface</hardwareInterface>
    </joint>
  </transmission>
  <transmission name="H1_F1J2_transmission">
    <type>transmission_interface/SimpleTransmission</type>
    <actuator name="H1_F1J2">
      <mechanicalReduction>1</mechanicalReduction>
    </actuator>
    <joint name="H1_F1J2">
      <hardwareInterface>EffortJointInterface</hardwareInterface>
    </joint>
  </transmission>
  <transmission name="H1_F1J3_transmission">
    <type>transmission_interface/SimpleTransmission</type>
    <actuator name="H1_F1J3">
      <mechanicalReduction>1</mechanicalReduction>
    </actuator>
    <joint name="H1_F1J3">
      <hardwareInterface>EffortJointInterface</hardwareInterface>
    </joint>
  </transmission>
  <!-- finger tip -->
  <link name="H1_F1_tip">
    <inertial>
      <origin rpy="0 0 0" xyz="-0.000925580990320645 -0.00495543398528436 0.0355865585792753"/>
      <mass value="0.00906322686585137"/>
      <inertia ixx="1.10049088227995E-06" ixy="-3.7290982171096E-09" ixz="-9.54389365908683E-09" iyy="1.36130530510584E-06" iyz="6.66133713720777E-08" izz="6.42259773618367E-07"/>
    </inertial>
    <visual>
      <origin rpy="0 0 0" xyz="0 0 0"/>
      <geometry>
        <mesh filename="package://fh_desc/meshes/omd-d18-tip.dae"/>
      </geometry>
      <material name="light_grey">
        <color rgba="0.75 0.75 0.75 1.0"/>
      </material>
    </visual>
    <collision>
      <origin rpy="0 0 0" xyz="0 0 0"/>
      <geometry>
        <mesh filename="package://fh_desc/meshes/omd-d18-tip.dae"/>
      </geometry>
      <material name="light_grey">
        <color rgba="0.75 0.75 0.75 1.0"/>
      </material>
    </collision>
  </link>
  <link name="H1_F1_optoforce"/>
  <joint name="H1_F1_tip_to_optoforce" type="fixed">
    <parent link="H1_F1_tip"/>
    <child link="H1_F1_optoforce"/>
    <origin rpy="-0.35 0 0" xyz="0 -0.006 0.046"/>
  </joint>
  <joint name="H1_F1_tip" type="fixed">
    <parent link="H1_F1_link_2"/>
    <child link="H1_F1_tip"/>
  </joint>
  <link name="H1_F2_palm_link">
    <inertial>
      <origin rpy="0 0 0" xyz="-0.00681802120880393 -0.00947020456878004 0.067587996682422"/>
      <mass value="0.0341482312344481"/>
      <inertia ixx="2.79747833772125E-05" ixy="-5.50900644725373E-08" ixz="-2.82072424927723E-07" iyy="2.67800858812928E-05" iyz="3.1953125069394E-06" izz="9.86122271726361E-06"/>
    </inertial>
    <visual>
      <origin rpy="0 0 0" xyz="0 0 0"/>
      <geometry>
        <mesh filename="package://fh_desc/meshes/v2/finger_palm_link.dae"/>
      </geometry>
      <material name="light_grey">
        <color rgba="0.75 0.75 0.75 1.0"/>
      </material>
    </visual>
    <!-- Collision mesh no needed as it is part of palm_link_simple.dae collision mesh -->
    <!--xacro:mesh_collision file_name="v2/finger_palm_link.dae">
        <origin xyz="0 0 0" rpy="0 0 0" />
        <xacro:light_grey/>
      </xacro:mesh_collision-->
  </link>
  <link name="H1_F2_base_link">
    <inertial>
      <origin rpy="0 0 0" xyz="-0.000142856770000038 0.0265691681336443 0.0538751581621436"/>
      <mass value="0.174652229503358"/>
      <inertia ixx="0.000298372741514267" ixy="-5.05751882577435E-07" ixz="1.94982779411417E-07" iyy="0.000299629589232877" iyz="2.79565205733806E-05" izz="0.000134889645145365"/>
    </inertial>
    <visual>
      <origin rpy="0 0 0" xyz="0 0 0"/>
      <geometry>
        <mesh filename="package://fh_desc/meshes/v2/finger_base_link_simple.dae"/>
      </geometry>
      <material name="light_grey">
        <color rgba="0.75 0.75 0.75 1.0"/>
      </material>
    </visual>
    <collision>
      <origin rpy="0 0 0" xyz="0 0 0"/>
      <geometry>
        <mesh filename="package://fh_desc/meshes/v2/finger_base_link_simple.dae"/>
      </geometry>
      <material name="light_grey">
        <color rgba="0.75 0.75 0.75 1.0"/>
      </material>
    </collision>
  </link>
  <link name="H1_F2_link_1">
    <inertial>
      <origin rpy="0 0 0" xyz="-0.000141876508729455 -0.00135409566494088 0.0277606215980989"/>
      <mass value="0.0827759744227546"/>
      <inertia ixx="4.61070151157777E-05" ixy="7.47741111557837E-08" ixz="-2.25165057702697E-07" iyy="5.27678327317508E-05" iyz="-3.64603343546298E-07" izz="2.89599551320955E-05"/>
    </inertial>
    <visual>
      <origin rpy="0 0 0" xyz="0 0 0"/>
      <geometry>
        <mesh filename="package://fh_desc/meshes/v2/finger_prox_link_simple.dae"/>
      </geometry>
      <material name="light_grey">
        <color rgba="0.75 0.75 0.75 1.0"/>
      </material>
    </visual>
    <collision>
      <origin rpy="0 0 0" xyz="0 0 0"/>
      <geometry>
        <mesh filename="package://fh_desc/meshes/v2/finger_prox_link_simple.dae"/>
      </geometry>
      <material name="light_grey">
        <color rgba="0.75 0.75 0.75 1.0"/>
      </material>
    </collision>
  </link>
  <link name="H1_F2_link_2">
    <inertial>
      <origin rpy="0 0 0" xyz="0.000506812071918918 -0.00091292934992606 0.0156620851768385"/>
      <mass value="0.0270049614151599"/>
      <inertia ixx="1.06942730265546E-05" ixy="-7.1810089794211E-09" ixz="-3.49957211410822E-07" iyy="1.05772889540593E-05" iyz="-8.38595987731518E-07" izz="3.27173446995846E-06"/>
    </inertial>
    <visual>
      <origin rpy="0 0 0" xyz="0 0 0"/>
      <geometry>
        <mesh filename="package://fh_desc/meshes/v2/finger_dist_link_simple.dae"/>
      </geometry>
      <material name="light_grey">
        <color rgba="0.75 0.75 0.75 1.0"/>
      </material>
    </visual>
    <collision>
      <origin rpy="0 0 0" xyz="0 0 0"/>
      <geometry>
        <mesh filename="package://fh_desc/meshes/v2/finger_dist_link_simple.dae"/>
      </geometry>
      <material name="light_grey">
        <color rgba="0.75 0.75 0.75 1.0"/>
      </material>
    </collision>
  </link>
  <joint name="H1_F2Palm" type="fixed">
    <origin rpy="0 0 0" xyz="0 0 0"/>
    <parent link="H1_insert_F2"/>
    <child link="H1_F2_palm_link"/>
  </joint>
  <joint name="H1_F2J1" type="revolute">
    <origin rpy="-8.8818E-16 -1.0061E-16 0.022402" xyz="0 0 0.00016528"/>
    <axis xyz="0 0 1"/>
    <parent link="H1_F2_palm_link"/>
    <child link="H1_F2_base_link"/>
    <limit effort="30" lower="-0.785398163397" upper="0.785398163397" velocity="1.0"/>
    <dynamics damping="0.0" friction="0.0"/>
  </joint>
  <joint name="H1_F2J2" type="revolute">
    <origin rpy="0.070695 6.9389E-16 2.0947E-16" xyz="0 0.035 0.11683"/>
    <axis xyz="1 0 0"/>
    <parent link="H1_F2_base_link"/>
    <child link="H1_F2_link_1"/>
    <limit effort="30" lower="-1.3962634016" upper="1.0471975512" velocity="1.0"/>
    <dynamics damping="0.0" friction="0.0"/>
  </joint>
  <joint name="H1_F2J3" type="revolute">
    <origin rpy="-0.0068649 1.7347E-18 1.6176E-16" xyz="0 0 0.06"/>
    <axis xyz="1 0 0"/>
    <parent link="H1_F2_link_1"/>
    <child link="H1_F2_link_2"/>
    <limit effort="30" lower="-1.0471975512" upper="1.57079632679" velocity="1.0"/>
    <dynamics damping="0.0" friction="0.0"/>
  </joint>
  <transmission name="H1_F2J1_transmission">
    <type>transmission_interface/SimpleTransmission</type>
    <actuator name="H1_F2J1">
      <mechanicalReduction>1</mechanicalReduction>
    </actuator>
    <joint name="H1_F2J1">
      <hardwareInterface>EffortJointInterface</hardwareInterface>
    </joint>
  </transmission>
  <transmission name="H1_F2J2_transmission">
    <type>transmission_interface/SimpleTransmission</type>
    <actuator name="H1_F2J2">
      <mechanicalReduction>1</mechanicalReduction>
    </actuator>
    <joint name="H1_F2J2">
      <hardwareInterface>EffortJointInterface</hardwareInterface>
    </joint>
  </transmission>
  <transmission name="H1_F2J3_transmission">
    <type>transmission_interface/SimpleTransmission</type>
    <actuator name="H1_F2J3">
      <mechanicalReduction>1</mechanicalReduction>
    </actuator>
    <joint name="H1_F2J3">
      <hardwareInterface>EffortJointInterface</hardwareInterface>
    </joint>
  </transmission>
  <!-- finger tip -->
  <link name="H1_F2_tip">
    <inertial>
      <origin rpy="0 0 0" xyz="-0.000925580990320645 -0.00495543398528436 0.0355865585792753"/>
      <mass value="0.00906322686585137"/>
      <inertia ixx="1.10049088227995E-06" ixy="-3.7290982171096E-09" ixz="-9.54389365908683E-09" iyy="1.36130530510584E-06" iyz="6.66133713720777E-08" izz="6.42259773618367E-07"/>
    </inertial>
    <visual>
      <origin rpy="0 0 0" xyz="0 0 0"/>
      <geometry>
        <mesh filename="package://fh_desc/meshes/omd-d18-tip.dae"/>
      </geometry>
      <material name="light_grey">
        <color rgba="0.75 0.75 0.75 1.0"/>
      </material>
    </visual>
    <collision>
      <origin rpy="0 0 0" xyz="0 0 0"/>
      <geometry>
        <mesh filename="package://fh_desc/meshes/omd-d18-tip.dae"/>
      </geometry>
      <material name="light_grey">
        <color rgba="0.75 0.75 0.75 1.0"/>
      </material>
    </collision>
  </link>
  <link name="H1_F2_optoforce"/>
  <joint name="H1_F2_tip_to_optoforce" type="fixed">
    <parent link="H1_F2_tip"/>
    <child link="H1_F2_optoforce"/>
    <origin rpy="-0.35 0 0" xyz="0 -0.006 0.046"/>
  </joint>
  <joint name="H1_F2_tip" type="fixed">
    <parent link="H1_F2_link_2"/>
    <child link="H1_F2_tip"/>
  </joint>
  <link name="H1_F3_palm_link">
    <inertial>
      <origin rpy="0 0 0" xyz="-0.00681802120880393 -0.00947020456878004 0.067587996682422"/>
      <mass value="0.0341482312344481"/>
      <inertia ixx="2.79747833772125E-05" ixy="-5.50900644725373E-08" ixz="-2.82072424927723E-07" iyy="2.67800858812928E-05" iyz="3.1953125069394E-06" izz="9.86122271726361E-06"/>
    </inertial>
    <visual>
      <origin rpy="0 0 0" xyz="0 0 0"/>
      <geometry>
        <mesh filename="package://fh_desc/meshes/v2/finger_palm_link.dae"/>
      </geometry>
      <material name="light_grey">
        <color rgba="0.75 0.75 0.75 1.0"/>
      </material>
    </visual>
    <!-- Collision mesh no needed as it is part of palm_link_simple.dae collision mesh -->
    <!--xacro:mesh_collision file_name="v2/finger_palm_link.dae">
        <origin xyz="0 0 0" rpy="0 0 0" />
        <xacro:light_grey/>
      </xacro:mesh_collision-->
  </link>
  <link name="H1_F3_base_link">
    <inertial>
      <origin rpy="0 0 0" xyz="-0.000142856770000038 0.0265691681336443 0.0538751581621436"/>
      <mass value="0.174652229503358"/>
      <inertia ixx="0.000298372741514267" ixy="-5.05751882577435E-07" ixz="1.94982779411417E-07" iyy="0.000299629589232877" iyz="2.79565205733806E-05" izz="0.000134889645145365"/>
    </inertial>
    <visual>
      <origin rpy="0 0 0" xyz="0 0 0"/>
      <geometry>
        <mesh filename="package://fh_desc/meshes/v2/finger_base_link_simple.dae"/>
      </geometry>
      <material name="light_grey">
        <color rgba="0.75 0.75 0.75 1.0"/>
      </material>
    </visual>
    <collision>
      <origin rpy="0 0 0" xyz="0 0 0"/>
      <geometry>
        <mesh filename="package://fh_desc/meshes/v2/finger_base_link_simple.dae"/>
      </geometry>
      <material name="light_grey">
        <color rgba="0.75 0.75 0.75 1.0"/>
      </material>
    </collision>
  </link>
  <link name="H1_F3_link_1">
    <inertial>
      <origin rpy="0 0 0" xyz="-0.000141876508729455 -0.00135409566494088 0.0277606215980989"/>
      <mass value="0.0827759744227546"/>
      <inertia ixx="4.61070151157777E-05" ixy="7.47741111557837E-08" ixz="-2.25165057702697E-07" iyy="5.27678327317508E-05" iyz="-3.64603343546298E-07" izz="2.89599551320955E-05"/>
    </inertial>
    <visual>
      <origin rpy="0 0 0" xyz="0 0 0"/>
      <geometry>
        <mesh filename="package://fh_desc/meshes/v2/finger_prox_link_simple.dae"/>
      </geometry>
      <material name="light_grey">
        <color rgba="0.75 0.75 0.75 1.0"/>
      </material>
    </visual>
    <collision>
      <origin rpy="0 0 0" xyz="0 0 0"/>
      <geometry>
        <mesh filename="package://fh_desc/meshes/v2/finger_prox_link_simple.dae"/>
      </geometry>
      <material name="light_grey">
        <color rgba="0.75 0.75 0.75 1.0"/>
      </material>
    </collision>
  </link>
  <link name="H1_F3_link_2">
    <inertial>
      <origin rpy="0 0 0" xyz="0.000506812071918918 -0.00091292934992606 0.0156620851768385"/>
      <mass value="0.0270049614151599"/>
      <inertia ixx="1.06942730265546E-05" ixy="-7.1810089794211E-09" ixz="-3.49957211410822E-07" iyy="1.05772889540593E-05" iyz="-8.38595987731518E-07" izz="3.27173446995846E-06"/>
    </inertial>
    <visual>
      <origin rpy="0 0 0" xyz="0 0 0"/>
      <geometry>
        <mesh filename="package://fh_desc/meshes/v2/finger_dist_link_simple.dae"/>
      </geometry>
      <material name="light_grey">
        <color rgba="0.75 0.75 0.75 1.0"/>
      </material>
    </visual>
    <collision>
      <origin rpy="0 0 0" xyz="0 0 0"/>
      <geometry>
        <mesh filename="package://fh_desc/meshes/v2/finger_dist_link_simple.dae"/>
      </geometry>
      <material name="light_grey">
        <color rgba="0.75 0.75 0.75 1.0"/>
      </material>
    </collision>
  </link>
  <joint name="H1_F3Palm" type="fixed">
    <origin rpy="0 0 0" xyz="0 0 0"/>
    <parent link="H1_insert_F3"/>
    <child link="H1_F3_palm_link"/>
  </joint>
  <joint name="H1_F3J1" type="revolute">
    <origin rpy="-8.8818E-16 -1.0061E-16 0.022402" xyz="0 0 0.00016528"/>
    <axis xyz="0 0 1"/>
    <parent link="H1_F3_palm_link"/>
    <child link="H1_F3_base_link"/>
    <limit effort="30" lower="-0.785398163397" upper="0.785398163397" velocity="1.0"/>
    <dynamics damping="0.0" friction="0.0"/>
  </joint>
  <joint name="H1_F3J2" type="revolute">
    <origin rpy="0.070695 6.9389E-16 2.0947E-16" xyz="0 0.035 0.11683"/>
    <axis xyz="1 0 0"/>
    <parent link="H1_F3_base_link"/>
    <child link="H1_F3_link_1"/>
    <limit effort="30" lower="-1.3962634016" upper="1.0471975512" velocity="1.0"/>
    <dynamics damping="0.0" friction="0.0"/>
  </joint>
  <joint name="H1_F3J3" type="revolute">
    <origin rpy="-0.0068649 1.7347E-18 1.6176E-16" xyz="0 0 0.06"/>
    <axis xyz="1 0 0"/>
    <parent link="H1_F3_link_1"/>
    <child link="H1_F3_link_2"/>
    <limit effort="30" lower="-1.0471975512" upper="1.57079632679" velocity="1.0"/>
    <dynamics damping="0.0" friction="0.0"/>
  </joint>
  <transmission name="H1_F3J1_transmission">
    <type>transmission_interface/SimpleTransmission</type>
    <actuator name="H1_F3J1">
      <mechanicalReduction>1</mechanicalReduction>
    </actuator>
    <joint name="H1_F3J1">
      <hardwareInterface>EffortJointInterface</hardwareInterface>
    </joint>
  </transmission>
  <transmission name="H1_F3J2_transmission">
    <type>transmission_interface/SimpleTransmission</type>
    <actuator name="H1_F3J2">
      <mechanicalReduction>1</mechanicalReduction>
    </actuator>
    <joint name="H1_F3J2">
      <hardwareInterface>EffortJointInterface</hardwareInterface>
    </joint>
  </transmission>
  <transmission name="H1_F3J3_transmission">
    <type>transmission_interface/SimpleTransmission</type>
    <actuator name="H1_F3J3">
      <mechanicalReduction>1</mechanicalReduction>
    </actuator>
    <joint name="H1_F3J3">
      <hardwareInterface>EffortJointInterface</hardwareInterface>
    </joint>
  </transmission>
  <!-- finger tip -->
  <link name="H1_F3_tip">
    <inertial>
      <origin rpy="0 0 0" xyz="-0.000925580990320645 -0.00495543398528436 0.0355865585792753"/>
      <mass value="0.00906322686585137"/>
      <inertia ixx="1.10049088227995E-06" ixy="-3.7290982171096E-09" ixz="-9.54389365908683E-09" iyy="1.36130530510584E-06" iyz="6.66133713720777E-08" izz="6.42259773618367E-07"/>
    </inertial>
    <visual>
      <origin rpy="0 0 0" xyz="0 0 0"/>
      <geometry>
        <mesh filename="package://fh_desc/meshes/omd-d18-tip.dae"/>
      </geometry>
      <material name="light_grey">
        <color rgba="0.75 0.75 0.75 1.0"/>
      </material>
    </visual>
    <collision>
      <origin rpy="0 0 0" xyz="0 0 0"/>
      <geometry>
        <mesh filename="package://fh_desc/meshes/omd-d18-tip.dae"/>
      </geometry>
      <material name="light_grey">
        <color rgba="0.75 0.75 0.75 1.0"/>
      </material>
    </collision>
  </link>
  <link name="H1_F3_optoforce"/>
  <joint name="H1_F3_tip_to_optoforce" type="fixed">
    <parent link="H1_F3_tip"/>
    <child link="H1_F3_optoforce"/>
    <origin rpy="-0.35 0 0" xyz="0 -0.006 0.046"/>
  </joint>
  <joint name="H1_F3_tip" type="fixed">
    <parent link="H1_F3_link_2"/>
    <child link="H1_F3_tip"/>
  </joint>
  
  
  <!-- <joint name="arm_to_hand" type="fixed">
    <parent link="ee_link"/>
    <child link="H1_base_attach"/>
    <origin rpy="1.57079632679 3.14159265359 1.57079632679" xyz="0.012 0.0 0.0"/>
  </joint> -->
  
  
  <gazebo reference="H1_F1J1">
    <implicitSpringDamper>1</implicitSpringDamper>
  </gazebo>
  <gazebo reference="H1_F1J2">
    <implicitSpringDamper>1</implicitSpringDamper>
  </gazebo>
  <gazebo reference="H1_F1J3">
    <implicitSpringDamper>1</implicitSpringDamper>
  </gazebo>
  <gazebo reference="H1_F2J1">
    <implicitSpringDamper>1</implicitSpringDamper>
  </gazebo>
  <gazebo reference="H1_F2J2">
    <implicitSpringDamper>1</implicitSpringDamper>
  </gazebo>
  <gazebo reference="H1_F2J3">
    <implicitSpringDamper>1</implicitSpringDamper>
  </gazebo>
  <gazebo reference="H1_F3J1">
    <implicitSpringDamper>1</implicitSpringDamper>
  </gazebo>
  <gazebo reference="H1_F3J2">
    <implicitSpringDamper>1</implicitSpringDamper>
  </gazebo>
  <gazebo reference="H1_F3J3">
    <implicitSpringDamper>1</implicitSpringDamper>
  </gazebo>
  
  <gazebo reference="H1_F1_link_1">  
    <kp>1000000.0</kp>
    <kd>100.0</kd>
    <mu1>1.5</mu1>
    <mu2>1.5</mu2>
    <fdir1>1 0 0</fdir1>
    <maxVel>1.0</maxVel>
    <minDepth>0.002</minDepth>
    
    <material>Gazebo/DarkGrey</material>
  </gazebo>
  <gazebo reference="H1_F1_link_2">
    <kp>1000000.0</kp>
    <kd>100.0</kd>
    <mu1>1.5</mu1>
    <mu2>1.5</mu2>
    <fdir1>1 0 0</fdir1>
    <maxVel>1.0</maxVel>
    <minDepth>0.002</minDepth>
    
    <material>Gazebo/DarkGrey</material>
  </gazebo><gazebo reference="H1_F1_tip">
    <kp>1000000.0</kp>
    <kd>100.0</kd>
    <mu1>1.5</mu1>
    <mu2>1.5</mu2>
    <fdir1>1 0 0</fdir1>
    <maxVel>1.0</maxVel>
    <minDepth>0.002</minDepth>
    
    <material>Gazebo/DarkGrey</material>
  </gazebo>
  
  <gazebo reference="H1_F2_link_1">
    <kp>1000000.0</kp>
    <kd>100.0</kd>
    <mu1>1.5</mu1>
    <mu2>1.5</mu2>
    <fdir1>1 0 0</fdir1>
    <maxVel>1.0</maxVel>
    <minDepth>0.002</minDepth>
    
    <material>Gazebo/DarkGrey</material>
  </gazebo>
  <gazebo reference="H1_F2_link_2">
    <kp>1000000.0</kp>
    <kd>100.0</kd>
    <mu1>1.5</mu1>
    <mu2>1.5</mu2>
    <fdir1>1 0 0</fdir1>
    <maxVel>1.0</maxVel>
    <minDepth>0.002</minDepth>
    
    <material>Gazebo/DarkGrey</material>
  </gazebo><gazebo reference="H1_F2_tip">
    <kp>1000000.0</kp>
    <kd>100.0</kd>
    <mu1>1.5</mu1>
    <mu2>1.5</mu2>
    <fdir1>1 0 0</fdir1>
    <maxVel>1.0</maxVel>
    <minDepth>0.002</minDepth>
    
    <material>Gazebo/DarkGrey</material>
  </gazebo>
  
  <gazebo reference="H1_F3_link_1">
    <kp>1000000.0</kp>
    <kd>100.0</kd>
    <mu1>1.5</mu1>
    <mu2>1.5</mu2>
    <fdir1>1 0 0</fdir1>
    <maxVel>1.0</maxVel>
    <minDepth>0.002</minDepth>
    
    <material>Gazebo/DarkGrey</material>
  </gazebo>
  <gazebo reference="H1_F3_link_2">
    <kp>1000000.0</kp>
    <kd>100.0</kd>
    <mu1>1.5</mu1>
    <mu2>1.5</mu2>
    <fdir1>1 0 0</fdir1>
    <maxVel>1.0</maxVel>
    <minDepth>0.002</minDepth>
    
    <material>Gazebo/DarkGrey</material>
  </gazebo><gazebo reference="H1_F3_tip">
    <kp>1000000.0</kp>
    <kd>100.0</kd>
    <mu1>1.5</mu1>
    <mu2>1.5</mu2>
    <fdir1>1 0 0</fdir1>
    <maxVel>1.0</maxVel>
    <minDepth>0.002</minDepth>
    
    <material>Gazebo/DarkGrey</material>
  </gazebo>
  
  <gazebo reference="H1_F1_base_link">
    <kp>1000000.0</kp>
    <kd>100.0</kd>
    <mu1>1.5</mu1>
    <mu2>1.5</mu2>
    <fdir1>1 0 0</fdir1>
    <maxVel>1.0</maxVel>
    <minDepth>0.002</minDepth>
    
    <material>Gazebo/DarkGrey</material>
  </gazebo>
  <gazebo reference="H1_F2_base_link">
    <kp>1000000.0</kp>
    <kd>100.0</kd>
    <mu1>1.5</mu1>
    <mu2>1.5</mu2>
    <fdir1>1 0 0</fdir1>
    <maxVel>1.0</maxVel>
    <minDepth>0.002</minDepth>
    
    <material>Gazebo/DarkGrey</material>
  </gazebo>
  <gazebo reference="H1_F3_base_link">
    <kp>1000000.0</kp>
    <kd>100.0</kd>
    <mu1>1.5</mu1>
    <mu2>1.5</mu2>
    <fdir1>1 0 0</fdir1>
    <maxVel>1.0</maxVel>
    <minDepth>0.002</minDepth>
    
    <material>Gazebo/DarkGrey</material>
  </gazebo>
  
  <gazebo reference="H1_F1_palm_link">
    <kp>1000000.0</kp>
    <kd>100.0</kd>
    <mu1>1.5</mu1>
    <mu2>1.5</mu2>
    <fdir1>1 0 0</fdir1>
    <maxVel>1.0</maxVel>
    <minDepth>0.002</minDepth>
    
    <material>Gazebo/DarkGrey</material>
  </gazebo>
  <gazebo reference="H1_F2_palm_link">
    <kp>1000000.0</kp>
    <kd>100.0</kd>
    <mu1>1.5</mu1>
    <mu2>1.5</mu2>
    <fdir1>1 0 0</fdir1>
    <maxVel>1.0</maxVel>
    <minDepth>0.002</minDepth>
    
    <material>Gazebo/DarkGrey</material>
  </gazebo>
  <gazebo reference="H1_F3_palm_link">
    <kp>1000000.0</kp>
    <kd>100.0</kd>
    <mu1>1.5</mu1>
    <mu2>1.5</mu2>
    <fdir1>1 0 0</fdir1>
    <maxVel>1.0</maxVel>
    <minDepth>0.002</minDepth>
    
    <material>Gazebo/DarkGrey</material>
  </gazebo>
  
  <gazebo reference="H1_base_link">
    <kp>1000000.0</kp>
    <kd>100.0</kd>
    <mu1>1.5</mu1>
    <mu2>1.5</mu2>
    <fdir1>1 0 0</fdir1>
    <maxVel>1.0</maxVel>
    <minDepth>0.002</minDepth>
    
    <material>Gazebo/DarkGrey</material>
  </gazebo>
  
</robot>

