<?xml version="1.0" ?>
<!-- =================================================================================== -->
<!-- |    This document was autogenerated by xacro from sia10f.gazebo.xacro            | -->
<!-- |    EDITING THIS FILE BY HAND IS NOT RECOMMENDED                                 | -->
<!-- =================================================================================== -->
<robot name="sia10f" xmlns:xacro="http://www.ros.org/wiki/xacro">
  <gazebo>
    <plugin filename="libgazebo_ros_control.so" name="ros_control">
      <robotNamespace>sia10f</robotNamespace>
      <!--<robotSimType>gazebo_ros_control/DefaultRobotHWSim</robotSimType>-->
    </plugin>
  </gazebo>
  <!-- link list -->
  <link name="base_link">
    <visual>
      <geometry>
        <mesh filename="package://sia10f_description/meshes/sia10f/visual/motoman_base.stl"/>
      </geometry>
      <material name="blue">
        <color rgba="0 0 1 1"/>
      </material>
    </visual>
    <collision>
      <geometry>
        <mesh filename="package://sia10f_description/meshes/sia10f/collision/motoman_base.stl"/>
      </geometry>
      <material name="yellow">
        <color rgba="0 1 1 1"/>
      </material>
    </collision>
    <inertial>
      <origin rpy="0 0 0" xyz="0 0 0"/>
      <mass value="1"/>
      <inertia ixx="1.0" ixy="0.0" ixz="0.0" iyy="1.0" iyz="0.0" izz="1.0"/>
    </inertial>
  </link>
  <link name="link_s">
    <visual>
      <geometry>
        <mesh filename="package://sia10f_description/meshes/sia10f/visual/motoman_axis_s.stl"/>
      </geometry>
      <material name="silver">
        <color rgba="0.8 0.8 0.8 1"/>
      </material>
    </visual>
    <collision>
      <geometry>
        <mesh filename="package://sia10f_description/meshes/sia10f/collision/motoman_axis_s.stl"/>
      </geometry>
      <material name="yellow"/>
    </collision>
    <inertial>
      <origin rpy="0 0 0" xyz="0 0 0"/>
      <mass value="1"/>
      <inertia ixx="1.0" ixy="0.0" ixz="0.0" iyy="1.0" iyz="0.0" izz="1.0"/>
    </inertial>
  </link>
  <link name="link_l">
    <visual>
      <origin rpy="1.57 3.1416 0" xyz="0 0 0"/>
      <geometry>
        <mesh filename="package://sia10f_description/meshes/sia10f/visual/motoman_axis_l.stl"/>
      </geometry>
      <material name="blue"/>
    </visual>
    <collision>
      <origin rpy="1.57 3.1416 0" xyz="0 0 0"/>
      <geometry>
        <mesh filename="package://sia10f_description/meshes/sia10f/collision/motoman_axis_l.stl"/>
      </geometry>
      <material name="yellow"/>
    </collision>
    <inertial>
      <origin rpy="0 0 0" xyz="0 0 0"/>
      <mass value="1"/>
      <inertia ixx="1.0" ixy="0.0" ixz="0.0" iyy="1.0" iyz="0.0" izz="1.0"/>
    </inertial>
  </link>
  <link name="link_e">
    <visual>
      <origin rpy="0 0 3.1415" xyz="0 0 0"/>
      <geometry>
        <mesh filename="package://sia10f_description/meshes/sia10f/visual/motoman_axis_e.stl"/>
      </geometry>
      <material name="silver"/>
    </visual>
    <collision>
      <origin rpy="0 0 3.1415" xyz="0 0 0"/>
      <geometry>
        <mesh filename="package://sia10f_description/meshes/sia10f/collision/motoman_axis_e.stl"/>
      </geometry>
      <material name="yellow"/>
    </collision>
    <inertial>
      <origin rpy="0 0 0" xyz="0 0 0"/>
      <mass value="1"/>
      <inertia ixx="1.0" ixy="0.0" ixz="0.0" iyy="1.0" iyz="0.0" izz="1.0"/>
    </inertial>
  </link>
  <link name="link_u">
    <visual>
      <origin rpy="1.57 -3.1415 0" xyz="0 0 0"/>
      <geometry>
        <mesh filename="package://sia10f_description/meshes/sia10f/visual/motoman_axis_u.stl"/>
      </geometry>
      <material name="blue"/>
    </visual>
    <collision>
      <origin rpy="1.57 -3.1415 0" xyz="0 0 0"/>
      <geometry>
        <mesh filename="package://sia10f_description/meshes/sia10f/collision/motoman_axis_u.stl"/>
      </geometry>
      <material name="yellow"/>
    </collision>
    <inertial>
      <origin rpy="0 0 0" xyz="0 0 0"/>
      <mass value="1"/>
      <inertia ixx="1.0" ixy="0.0" ixz="0.0" iyy="1.0" iyz="0.0" izz="1.0"/>
    </inertial>
  </link>
  <link name="link_r">
    <visual>
      <origin rpy="0 0 3.1416" xyz="0 0 0"/>
      <geometry>
        <mesh filename="package://sia10f_description/meshes/sia10f/visual/motoman_axis_r.stl"/>
      </geometry>
      <material name="silver"/>
    </visual>
    <collision>
      <origin rpy="0 0 3.1416" xyz="0 0 0"/>
      <geometry>
        <mesh filename="package://sia10f_description/meshes/sia10f/collision/motoman_axis_r.stl"/>
      </geometry>
      <material name="yellow"/>
    </collision>
    <inertial>
      <origin rpy="0 0 0" xyz="0 0 0"/>
      <mass value="1"/>
      <inertia ixx="1.0" ixy="0.0" ixz="0.0" iyy="1.0" iyz="0.0" izz="1.0"/>
    </inertial>
  </link>
  <link name="link_b">
    <visual>
      <origin rpy="-1.57 0 3.1416" xyz="0 0 0"/>
      <geometry>
        <mesh filename="package://sia10f_description/meshes/sia10f/visual/motoman_axis_b.stl"/>
      </geometry>
      <material name="blue"/>
    </visual>
    <collision>
      <origin rpy="-1.57 0 3.1416" xyz="0 0 0"/>
      <geometry>
        <mesh filename="package://sia10f_description/meshes/sia10f/collision/motoman_axis_b.stl"/>
      </geometry>
      <material name="yellow"/>
    </collision>
    <inertial>
      <origin rpy="0 0 0" xyz="0 0 0"/>
      <mass value="1"/>
      <inertia ixx="1.0" ixy="0.0" ixz="0.0" iyy="1.0" iyz="0.0" izz="1.0"/>
    </inertial>
  </link>
  <link name="link_t">
    <visual>
      <geometry>
        <mesh filename="package://sia10f_description/meshes/sia10f/visual/motoman_axis_t.stl"/>
      </geometry>
      <material name="silver"/>
    </visual>
    <collision>
      <geometry>
        <mesh filename="package://sia10f_description/meshes/sia10f/collision/motoman_axis_t.stl"/>
      </geometry>
      <material name="yellow"/>
    </collision>
    <inertial>
      <origin rpy="0 0 0" xyz="0 0 0"/>
      <mass value="1"/>
      <inertia ixx="1.0" ixy="0.0" ixz="0.0" iyy="1.0" iyz="0.0" izz="1.0"/>
    </inertial>
  </link>
  <link name="link_tool0"/>
  <!-- end of link list -->
  <!-- joint list -->
  <joint name="joint_s" type="revolute">
    <parent link="base_link"/>
    <child link="link_s"/>
    <origin rpy="0 0 0" xyz="0 0 0.36"/>
    <axis xyz="0 0 1"/>
    <limit effort="0" lower="-3.1415" upper="3.1415" velocity="2.9670"/>
  </joint>
  <joint name="joint_l" type="revolute">
    <parent link="link_s"/>
    <child link="link_l"/>
    <origin rpy="0 0 0" xyz="0 0 0"/>
    <axis xyz="0 1 0"/>
    <limit effort="0" lower="-1.9198" upper="1.9198" velocity="2.9670"/>
  </joint>
  <joint name="joint_e" type="revolute">
    <parent link="link_l"/>
    <child link="link_e"/>
    <origin rpy="0 0 0" xyz="0 0 0.36"/>
    <axis xyz="0 0 1"/>
    <limit effort="0" lower="-2.9670" upper="2.9670" velocity="2.9670"/>
  </joint>
  <joint name="joint_u" type="revolute">
    <parent link="link_e"/>
    <child link="link_u"/>
    <origin rpy="0 0 0" xyz="0 0 0"/>
    <axis xyz="0 -1 0"/>
    <limit effort="0" lower="-2.3561" upper="2.3561" velocity="2.9670"/>
  </joint>
  <joint name="joint_r" type="revolute">
    <parent link="link_u"/>
    <child link="link_r"/>
    <origin rpy="0 0 0" xyz="0 0 0.360"/>
    <axis xyz="0 0 -1"/>
    <limit effort="0" lower="-3.1415" upper="3.1415" velocity="3.4906"/>
  </joint>
  <joint name="joint_b" type="revolute">
    <parent link="link_r"/>
    <child link="link_b"/>
    <origin rpy="0 0 0" xyz="0 0 0"/>
    <axis xyz="0 -1 0"/>
    <limit effort="0" lower="-1.9198" upper="1.9198" velocity="3.4906"/>
  </joint>
  <joint name="joint_t" type="revolute">
    <parent link="link_b"/>
    <child link="link_t"/>
    <origin rpy="0 0 0" xyz="0 0 0.155"/>
    <axis xyz="0 0 -1"/>
    <limit effort="0" lower="-3.1415" upper="3.1415" velocity="6.9813"/>
  </joint>
  <joint name="joint_tool0" type="fixed">
    <origin rpy="0 0 -3.1415926535" xyz="0 0 0.0"/>
    <parent link="link_t"/>
    <child link="link_tool0"/>
  </joint>
  <!-- end of joint list -->
  <!-- ROS base_link (via link_l) to Motoman Robot (not Base) Frame transform -->
  <link name="rworld"/>
  <joint name="link_l-rworld" type="fixed">
    <origin rpy="0 0 0" xyz="0 0 0"/>
    <parent link="link_l"/>
    <child link="rworld"/>
  </joint>
  <!-- link list -->
  <link name="world"/>
  <link name="robotcell">
    <visual>
      <geometry>
        <mesh filename="package://sia10f_description/meshes/robotcell/visual/robotcell.stl"/>
      </geometry>
      <material name="white">
        <color rgba="1 1 1 1"/>
      </material>
    </visual>
    <collision>
      <geometry>
        <mesh filename="package://sia10f_description/meshes/robotcell/collision/robotcell_c.stl"/>
      </geometry>
      <material name="yellow">
        <color rgba="0 1 1 1"/>
      </material>
    </collision>
    <inertial>
      <origin rpy="0 0 0" xyz="0 0 0"/>
      <mass value="60"/>
      <inertia ixx="1.0" ixy="0.0" ixz="0.0" iyy="1.0" iyz="0.0" izz="1.0"/>
      <origin xyz="-0.6 0.5 0.0"/>
    </inertial>
  </link>
  <link name="base">
    <visual>
      <geometry>
        <mesh filename="package://sia10f_description/meshes/robotcell/visual/base_sia10f.stl"/>
      </geometry>
      <material name="white">
        <color rgba="1 1 1 1"/>
      </material>
    </visual>
    <collision>
      <geometry>
        <mesh filename="package://sia10f_description/meshes/robotcell/collision/base_sia10f_c.stl"/>
      </geometry>
      <material name="yellow">
        <color rgba="0 1 1 1"/>
      </material>
    </collision>
    <inertial>
      <origin rpy="0 0 0" xyz="0 0 0"/>
      <mass value="10"/>
      <inertia ixx="1.0" ixy="0.0" ixz="0.0" iyy="1.0" iyz="0.0" izz="1.0"/>
    </inertial>
  </link>
  <!-- end of link list -->
  <!-- joint list -->
  <joint name="world_base" type="fixed">
    <parent link="world"/>
    <child link="robotcell"/>
    <origin rpy="0 -1.57 0" xyz="0 0 0.84"/>
  </joint>
  <joint name="connection1" type="fixed">
    <parent link="robotcell"/>
    <child link="base"/>
    <origin rpy="0 1.57 0" xyz="0.0075 0 0"/>
  </joint>
  <!-- end of joint list -->
  <!-- ROS base_link (via link_l) to Motoman Robot (not Base) Frame transform -->
  <joint name="robot_base" type="fixed">
    <parent link="base"/>
    <child link="base_link"/>
    <origin rpy="0 0 0" xyz="0 0 0.0075"/>
  </joint>
  <gazebo reference="world">
    <turnGravityOff>false</turnGravityOff>
    <selfCollide>true</selfCollide>
    <material>Gazebo/White</material>
  </gazebo>
  <gazebo reference="robotcell">
    <turnGravityOff>false</turnGravityOff>
    <selfCollide>true</selfCollide>
    <material>Gazebo/White</material>
  </gazebo>
  <gazebo reference="base">
    <turnGravityOff>false</turnGravityOff>
    <selfCollide>true</selfCollide>
    <material>Gazebo/White</material>
  </gazebo>
  <gazebo reference="base_link">
    <turnGravityOff>false</turnGravityOff>
    <selfCollide>true</selfCollide>
    <material>Gazebo/Blue</material>
  </gazebo>
  <gazebo reference="link_s">
    <turnGravityOff>false</turnGravityOff>
    <selfCollide>true</selfCollide>
    <material>Gazebo/White</material>
  </gazebo>
  <gazebo reference="link_l">
    <turnGravityOff>false</turnGravityOff>
    <selfCollide>true</selfCollide>
    <material>Gazebo/Blue</material>
  </gazebo>
  <gazebo reference="link_e">
    <turnGravityOff>false</turnGravityOff>
    <selfCollide>true</selfCollide>
    <material>Gazebo/White</material>
  </gazebo>
  <gazebo reference="link_u">
    <turnGravityOff>false</turnGravityOff>
    <selfCollide>true</selfCollide>
    <material>Gazebo/Blue</material>
  </gazebo>
  <gazebo reference="link_r">
    <turnGravityOff>false</turnGravityOff>
    <selfCollide>true</selfCollide>
    <material>Gazebo/White</material>
  </gazebo>
  <gazebo reference="link_b">
    <turnGravityOff>false</turnGravityOff>
    <selfCollide>true</selfCollide>
    <material>Gazebo/Blue</material>
  </gazebo>
  <gazebo reference="link_t">
    <turnGravityOff>false</turnGravityOff>
    <selfCollide>true</selfCollide>
    <material>Gazebo/Gold</material>
  </gazebo>
  <transmission name="trans_s">
    <type>transmission_interface/SimpleTransmission</type>
    <joint name="joint_s">
      <hardwareInterface>PositionJointInterface</hardwareInterface>
    </joint>
    <actuator name="s_motor">
      <mechanicalReduction>50</mechanicalReduction>
      <hardwareInterface>PositionJointInterface</hardwareInterface>
    </actuator>
  </transmission>
  <transmission name="trans_l">
    <type>transmission_interface/SimpleTransmission</type>
    <joint name="joint_l">
      <hardwareInterface>PositionJointInterface</hardwareInterface>
    </joint>
    <actuator name="l_motor">
      <mechanicalReduction>50</mechanicalReduction>
      <hardwareInterface>PositionJointInterface</hardwareInterface>
    </actuator>
  </transmission>
  <transmission name="trans_e">
    <type>transmission_interface/SimpleTransmission</type>
    <joint name="joint_e">
      <hardwareInterface>PositionJointInterface</hardwareInterface>
    </joint>
    <actuator name="e_motor">
      <mechanicalReduction>50</mechanicalReduction>
      <hardwareInterface>PositionJointInterface</hardwareInterface>
    </actuator>
  </transmission>
  <transmission name="trans_u">
    <type>transmission_interface/SimpleTransmission</type>
    <joint name="joint_u">
      <hardwareInterface>PositionJointInterface</hardwareInterface>
    </joint>
    <actuator name="u_motor">
      <mechanicalReduction>50</mechanicalReduction>
      <hardwareInterface>PositionJointInterface</hardwareInterface>
    </actuator>
  </transmission>
  <transmission name="trans_r">
    <type>transmission_interface/SimpleTransmission</type>
    <joint name="joint_r">
      <hardwareInterface>PositionJointInterface</hardwareInterface>
    </joint>
    <actuator name="r_motor">
      <mechanicalReduction>50</mechanicalReduction>
      <hardwareInterface>PositionJointInterface</hardwareInterface>
    </actuator>
  </transmission>
  <transmission name="trans_b">
    <type>transmission_interface/SimpleTransmission</type>
    <joint name="joint_b">
      <hardwareInterface>PositionJointInterface</hardwareInterface>
    </joint>
    <actuator name="b_motor">
      <mechanicalReduction>50</mechanicalReduction>
      <hardwareInterface>PositionJointInterface</hardwareInterface>
    </actuator>
  </transmission>
  <transmission name="trans_t">
    <type>transmission_interface/SimpleTransmission</type>
    <joint name="joint_t">
      <hardwareInterface>PositionJointInterface</hardwareInterface>
    </joint>
    <actuator name="t_motor">
      <mechanicalReduction>50</mechanicalReduction>
      <hardwareInterface>PositionJointInterface</hardwareInterface>
    </actuator>
  </transmission>
</robot>

